[2025-05-02T16:01:29.915+0000] {task_context_logger.py:104} ERROR - Executor reports task instance <TaskInstance: weather_data_pipeline.collect_data scheduled__2025-05-01T00:00:00+00:00 [queued]> finished (failed) although the task says it's queued. (Info: None) Was the task killed externally?
