[2025-05-02T15:49:10.119+0000] {local_task_job_runner.py:120} INFO - ::group::Pre task execution logs
[2025-05-02T15:49:10.179+0000] {taskinstance.py:2076} INFO - Dependencies all met for dep_context=non-requeueable deps ti=<TaskInstance: weather_data_pipeline.collect_data manual__2025-05-02T15:49:03.266425+00:00 [queued]>
[2025-05-02T15:49:10.189+0000] {taskinstance.py:2076} INFO - Dependencies all met for dep_context=requeueable deps ti=<TaskInstance: weather_data_pipeline.collect_data manual__2025-05-02T15:49:03.266425+00:00 [queued]>
[2025-05-02T15:49:10.190+0000] {taskinstance.py:2306} INFO - Starting attempt 1 of 1
[2025-05-02T15:49:10.212+0000] {taskinstance.py:2330} INFO - Executing <Task(BashOperator): collect_data> on 2025-05-02 15:49:03.266425+00:00
[2025-05-02T15:49:10.235+0000] {warnings.py:110} WARNING - /home/***/.local/lib/python3.12/site-packages/***/task/task_runner/standard_task_runner.py:61: DeprecationWarning: This process (pid=89) is multi-threaded, use of fork() may lead to deadlocks in the child.
  pid = os.fork()

[2025-05-02T15:49:10.239+0000] {standard_task_runner.py:63} INFO - Started process 91 to run task
[2025-05-02T15:49:10.239+0000] {standard_task_runner.py:90} INFO - Running: ['***', 'tasks', 'run', 'weather_data_pipeline', 'collect_data', 'manual__2025-05-02T15:49:03.266425+00:00', '--job-id', '10', '--raw', '--subdir', 'DAGS_FOLDER/weather_pipeline_dag.py', '--cfg-path', '/tmp/tmp3i81d_ao']
[2025-05-02T15:49:10.252+0000] {standard_task_runner.py:91} INFO - Job 10: Subtask collect_data
[2025-05-02T15:49:10.332+0000] {task_command.py:426} INFO - Running <TaskInstance: weather_data_pipeline.collect_data manual__2025-05-02T15:49:03.266425+00:00 [running]> on host ac5fc77d8294
[2025-05-02T15:49:10.454+0000] {taskinstance.py:2648} INFO - Exporting env vars: AIRFLOW_CTX_DAG_OWNER='***' AIRFLOW_CTX_DAG_ID='weather_data_pipeline' AIRFLOW_CTX_TASK_ID='collect_data' AIRFLOW_CTX_EXECUTION_DATE='2025-05-02T15:49:03.266425+00:00' AIRFLOW_CTX_TRY_NUMBER='1' AIRFLOW_CTX_DAG_RUN_ID='manual__2025-05-02T15:49:03.266425+00:00'
[2025-05-02T15:49:10.456+0000] {taskinstance.py:430} INFO - ::endgroup::
[2025-05-02T15:49:10.481+0000] {subprocess.py:63} INFO - Tmp dir root location: /tmp
[2025-05-02T15:49:10.484+0000] {subprocess.py:75} INFO - Running command: ['/usr/bin/bash', '-c', 'python /opt/***/scripts/collect_data.py']
[2025-05-02T15:49:10.514+0000] {subprocess.py:86} INFO - Output:
[2025-05-02T15:49:12.548+0000] {subprocess.py:93} INFO - API Response:  {'coord': {'lon': 67.0822, 'lat': 24.9056}, 'weather': [{'id': 721, 'main': 'Haze', 'description': 'haze', 'icon': '50n'}], 'base': 'stations', 'main': {'temp': 28.9, 'feels_like': 31.65, 'temp_min': 28.9, 'temp_max': 28.9, 'pressure': 1006, 'humidity': 65, 'sea_level': 1006, 'grnd_level': 1003}, 'visibility': 5000, 'wind': {'speed': 5.14, 'deg': 260}, 'clouds': {'all': 20}, 'dt': 1746200922, 'sys': {'type': 1, 'id': 7576, 'country': 'PK', 'sunrise': 1746147324, 'sunset': 1746194506}, 'timezone': 18000, 'id': 1174872, 'name': 'Karachi', 'cod': 200}
[2025-05-02T15:49:12.550+0000] {subprocess.py:93} INFO - Traceback (most recent call last):
[2025-05-02T15:49:12.551+0000] {subprocess.py:93} INFO -   File "/opt/***/scripts/collect_data.py", line 78, in <module>
[2025-05-02T15:49:12.553+0000] {subprocess.py:93} INFO -     collect_weather_data()
[2025-05-02T15:49:12.554+0000] {subprocess.py:93} INFO -   File "/opt/***/scripts/collect_data.py", line 61, in collect_weather_data
[2025-05-02T15:49:12.557+0000] {subprocess.py:93} INFO -     with open(filename, 'x', newline='') as csvfile:
[2025-05-02T15:49:12.559+0000] {subprocess.py:93} INFO -          ^^^^^^^^^^^^^^^^^^^^^^^^^^^^^^^
[2025-05-02T15:49:12.560+0000] {subprocess.py:93} INFO - FileNotFoundError: [Errno 2] No such file or directory: 'data/raw/raw_data.csv'
[2025-05-02T15:49:12.624+0000] {subprocess.py:97} INFO - Command exited with return code 1
[2025-05-02T15:49:12.629+0000] {taskinstance.py:441} INFO - ::group::Post task execution logs
[2025-05-02T15:49:12.705+0000] {taskinstance.py:2905} ERROR - Task failed with exception
Traceback (most recent call last):
  File "/home/airflow/.local/lib/python3.12/site-packages/airflow/models/taskinstance.py", line 465, in _execute_task
    result = _execute_callable(context=context, **execute_callable_kwargs)
             ^^^^^^^^^^^^^^^^^^^^^^^^^^^^^^^^^^^^^^^^^^^^^^^^^^^^^^^^^^^^^
  File "/home/airflow/.local/lib/python3.12/site-packages/airflow/models/taskinstance.py", line 432, in _execute_callable
    return execute_callable(context=context, **execute_callable_kwargs)
           ^^^^^^^^^^^^^^^^^^^^^^^^^^^^^^^^^^^^^^^^^^^^^^^^^^^^^^^^^^^^
  File "/home/airflow/.local/lib/python3.12/site-packages/airflow/models/baseoperator.py", line 400, in wrapper
    return func(self, *args, **kwargs)
           ^^^^^^^^^^^^^^^^^^^^^^^^^^^
  File "/home/airflow/.local/lib/python3.12/site-packages/airflow/operators/bash.py", line 243, in execute
    raise AirflowException(
airflow.exceptions.AirflowException: Bash command failed. The command returned a non-zero exit code 1.
[2025-05-02T15:49:12.717+0000] {taskinstance.py:1206} INFO - Marking task as FAILED. dag_id=weather_data_pipeline, task_id=collect_data, run_id=manual__2025-05-02T15:49:03.266425+00:00, execution_date=20250502T154903, start_date=20250502T154910, end_date=20250502T154912
[2025-05-02T15:49:12.746+0000] {standard_task_runner.py:110} ERROR - Failed to execute job 10 for task collect_data (Bash command failed. The command returned a non-zero exit code 1.; 91)
[2025-05-02T15:49:12.792+0000] {local_task_job_runner.py:240} INFO - Task exited with return code 1
[2025-05-02T15:49:12.873+0000] {taskinstance.py:3498} INFO - 0 downstream tasks scheduled from follow-on schedule check
[2025-05-02T15:49:12.895+0000] {local_task_job_runner.py:222} INFO - ::endgroup::
