[2025-05-02T17:05:17.968+0000] {task_context_logger.py:104} ERROR - Executor reports task instance <TaskInstance: weather_data_pipeline.collect_data manual__2025-05-02T17:04:33.268002+00:00 [queued]> finished (failed) although the task says it's queued. (Info: None) Was the task killed externally?
