[2025-05-02T15:54:58.803+0000] {local_task_job_runner.py:120} INFO - ::group::Pre task execution logs
[2025-05-02T15:54:58.883+0000] {taskinstance.py:2076} INFO - Dependencies all met for dep_context=non-requeueable deps ti=<TaskInstance: weather_data_pipeline.preprocess_data manual__2025-05-02T15:54:46.135169+00:00 [queued]>
[2025-05-02T15:54:58.896+0000] {taskinstance.py:2076} INFO - Dependencies all met for dep_context=requeueable deps ti=<TaskInstance: weather_data_pipeline.preprocess_data manual__2025-05-02T15:54:46.135169+00:00 [queued]>
[2025-05-02T15:54:58.898+0000] {taskinstance.py:2306} INFO - Starting attempt 1 of 1
[2025-05-02T15:54:58.921+0000] {taskinstance.py:2330} INFO - Executing <Task(BashOperator): preprocess_data> on 2025-05-02 15:54:46.135169+00:00
[2025-05-02T15:54:58.934+0000] {warnings.py:110} WARNING - /home/***/.local/lib/python3.12/site-packages/***/task/task_runner/standard_task_runner.py:61: DeprecationWarning: This process (pid=167) is multi-threaded, use of fork() may lead to deadlocks in the child.
  pid = os.fork()

[2025-05-02T15:54:58.936+0000] {standard_task_runner.py:63} INFO - Started process 169 to run task
[2025-05-02T15:54:58.934+0000] {standard_task_runner.py:90} INFO - Running: ['***', 'tasks', 'run', 'weather_data_pipeline', 'preprocess_data', 'manual__2025-05-02T15:54:46.135169+00:00', '--job-id', '12', '--raw', '--subdir', 'DAGS_FOLDER/weather_pipeline_dag.py', '--cfg-path', '/tmp/tmpnv2s2n_s']
[2025-05-02T15:54:58.939+0000] {standard_task_runner.py:91} INFO - Job 12: Subtask preprocess_data
[2025-05-02T15:54:59.003+0000] {task_command.py:426} INFO - Running <TaskInstance: weather_data_pipeline.preprocess_data manual__2025-05-02T15:54:46.135169+00:00 [running]> on host ac5fc77d8294
[2025-05-02T15:54:59.098+0000] {taskinstance.py:2648} INFO - Exporting env vars: AIRFLOW_CTX_DAG_OWNER='***' AIRFLOW_CTX_DAG_ID='weather_data_pipeline' AIRFLOW_CTX_TASK_ID='preprocess_data' AIRFLOW_CTX_EXECUTION_DATE='2025-05-02T15:54:46.135169+00:00' AIRFLOW_CTX_TRY_NUMBER='1' AIRFLOW_CTX_DAG_RUN_ID='manual__2025-05-02T15:54:46.135169+00:00'
[2025-05-02T15:54:59.100+0000] {taskinstance.py:430} INFO - ::endgroup::
[2025-05-02T15:54:59.118+0000] {subprocess.py:63} INFO - Tmp dir root location: /tmp
[2025-05-02T15:54:59.120+0000] {subprocess.py:75} INFO - Running command: ['/usr/bin/bash', '-c', 'python /opt/***/scripts/preprocess_data.py']
[2025-05-02T15:54:59.150+0000] {subprocess.py:86} INFO - Output:
[2025-05-02T15:55:01.312+0000] {subprocess.py:93} INFO - Traceback (most recent call last):
[2025-05-02T15:55:01.320+0000] {subprocess.py:93} INFO -   File "/opt/***/scripts/preprocess_data.py", line 13, in <module>
[2025-05-02T15:55:01.321+0000] {subprocess.py:93} INFO -     from sklearn.preprocessing import StandardScaler
[2025-05-02T15:55:01.323+0000] {subprocess.py:93} INFO - ModuleNotFoundError: No module named 'sklearn'
[2025-05-02T15:55:01.600+0000] {subprocess.py:97} INFO - Command exited with return code 1
[2025-05-02T15:55:01.621+0000] {taskinstance.py:441} INFO - ::group::Post task execution logs
[2025-05-02T15:55:01.887+0000] {taskinstance.py:2905} ERROR - Task failed with exception
Traceback (most recent call last):
  File "/home/airflow/.local/lib/python3.12/site-packages/airflow/models/taskinstance.py", line 465, in _execute_task
    result = _execute_callable(context=context, **execute_callable_kwargs)
             ^^^^^^^^^^^^^^^^^^^^^^^^^^^^^^^^^^^^^^^^^^^^^^^^^^^^^^^^^^^^^
  File "/home/airflow/.local/lib/python3.12/site-packages/airflow/models/taskinstance.py", line 432, in _execute_callable
    return execute_callable(context=context, **execute_callable_kwargs)
           ^^^^^^^^^^^^^^^^^^^^^^^^^^^^^^^^^^^^^^^^^^^^^^^^^^^^^^^^^^^^
  File "/home/airflow/.local/lib/python3.12/site-packages/airflow/models/baseoperator.py", line 400, in wrapper
    return func(self, *args, **kwargs)
           ^^^^^^^^^^^^^^^^^^^^^^^^^^^
  File "/home/airflow/.local/lib/python3.12/site-packages/airflow/operators/bash.py", line 243, in execute
    raise AirflowException(
airflow.exceptions.AirflowException: Bash command failed. The command returned a non-zero exit code 1.
[2025-05-02T15:55:01.910+0000] {taskinstance.py:1206} INFO - Marking task as FAILED. dag_id=weather_data_pipeline, task_id=preprocess_data, run_id=manual__2025-05-02T15:54:46.135169+00:00, execution_date=20250502T155446, start_date=20250502T155458, end_date=20250502T155501
[2025-05-02T15:55:01.942+0000] {standard_task_runner.py:110} ERROR - Failed to execute job 12 for task preprocess_data (Bash command failed. The command returned a non-zero exit code 1.; 169)
[2025-05-02T15:55:01.972+0000] {local_task_job_runner.py:240} INFO - Task exited with return code 1
[2025-05-02T15:55:01.997+0000] {taskinstance.py:3498} INFO - 0 downstream tasks scheduled from follow-on schedule check
[2025-05-02T15:55:01.999+0000] {local_task_job_runner.py:222} INFO - ::endgroup::
