[2025-05-02T16:00:25.081+0000] {local_task_job_runner.py:120} INFO - ::group::Pre task execution logs
[2025-05-02T16:00:25.154+0000] {taskinstance.py:2076} INFO - Dependencies all met for dep_context=non-requeueable deps ti=<TaskInstance: weather_data_pipeline.collect_data manual__2025-05-02T15:54:46.135169+00:00 [queued]>
[2025-05-02T16:00:25.164+0000] {taskinstance.py:2076} INFO - Dependencies all met for dep_context=requeueable deps ti=<TaskInstance: weather_data_pipeline.collect_data manual__2025-05-02T15:54:46.135169+00:00 [queued]>
[2025-05-02T16:00:25.165+0000] {taskinstance.py:2306} INFO - Starting attempt 2 of 2
[2025-05-02T16:00:25.182+0000] {taskinstance.py:2330} INFO - Executing <Task(BashOperator): collect_data> on 2025-05-02 15:54:46.135169+00:00
[2025-05-02T16:00:25.210+0000] {warnings.py:110} WARNING - /home/***/.local/lib/python3.12/site-packages/***/task/task_runner/standard_task_runner.py:61: DeprecationWarning: This process (pid=249) is multi-threaded, use of fork() may lead to deadlocks in the child.
  pid = os.fork()

[2025-05-02T16:00:25.213+0000] {standard_task_runner.py:63} INFO - Started process 251 to run task
[2025-05-02T16:00:25.220+0000] {standard_task_runner.py:90} INFO - Running: ['***', 'tasks', 'run', 'weather_data_pipeline', 'collect_data', 'manual__2025-05-02T15:54:46.135169+00:00', '--job-id', '13', '--raw', '--subdir', 'DAGS_FOLDER/weather_pipeline_dag.py', '--cfg-path', '/tmp/tmp9hvrl06a']
[2025-05-02T16:00:25.227+0000] {standard_task_runner.py:91} INFO - Job 13: Subtask collect_data
[2025-05-02T16:00:25.413+0000] {task_command.py:426} INFO - Running <TaskInstance: weather_data_pipeline.collect_data manual__2025-05-02T15:54:46.135169+00:00 [running]> on host ac5fc77d8294
[2025-05-02T16:00:25.580+0000] {taskinstance.py:2648} INFO - Exporting env vars: AIRFLOW_CTX_DAG_OWNER='***' AIRFLOW_CTX_DAG_ID='weather_data_pipeline' AIRFLOW_CTX_TASK_ID='collect_data' AIRFLOW_CTX_EXECUTION_DATE='2025-05-02T15:54:46.135169+00:00' AIRFLOW_CTX_TRY_NUMBER='2' AIRFLOW_CTX_DAG_RUN_ID='manual__2025-05-02T15:54:46.135169+00:00'
[2025-05-02T16:00:25.586+0000] {taskinstance.py:430} INFO - ::endgroup::
[2025-05-02T16:00:25.599+0000] {subprocess.py:63} INFO - Tmp dir root location: /tmp
[2025-05-02T16:00:25.602+0000] {subprocess.py:75} INFO - Running command: ['/usr/bin/bash', '-c', 'python /opt/***/scripts/collect_data.py']
[2025-05-02T16:00:25.649+0000] {subprocess.py:86} INFO - Output:
[2025-05-02T16:00:37.304+0000] {subprocess.py:93} INFO - Traceback (most recent call last):
[2025-05-02T16:00:37.313+0000] {subprocess.py:93} INFO -   File "/home/***/.local/lib/python3.12/site-packages/urllib3/connection.py", line 198, in _new_conn
[2025-05-02T16:00:37.314+0000] {subprocess.py:93} INFO -     sock = connection.create_connection(
[2025-05-02T16:00:37.315+0000] {subprocess.py:93} INFO -            ^^^^^^^^^^^^^^^^^^^^^^^^^^^^^
[2025-05-02T16:00:37.316+0000] {subprocess.py:93} INFO -   File "/home/***/.local/lib/python3.12/site-packages/urllib3/util/connection.py", line 60, in create_connection
[2025-05-02T16:00:37.317+0000] {subprocess.py:93} INFO -     for res in socket.getaddrinfo(host, port, family, socket.SOCK_STREAM):
[2025-05-02T16:00:37.318+0000] {subprocess.py:93} INFO -                ^^^^^^^^^^^^^^^^^^^^^^^^^^^^^^^^^^^^^^^^^^^^^^^^^^^^^^^^^^
[2025-05-02T16:00:37.319+0000] {subprocess.py:93} INFO -   File "/usr/local/lib/python3.12/socket.py", line 963, in getaddrinfo
[2025-05-02T16:00:37.319+0000] {subprocess.py:93} INFO -     for res in _socket.getaddrinfo(host, port, family, type, proto, flags):
[2025-05-02T16:00:37.320+0000] {subprocess.py:93} INFO -                ^^^^^^^^^^^^^^^^^^^^^^^^^^^^^^^^^^^^^^^^^^^^^^^^^^^^^^^^^^^
[2025-05-02T16:00:37.321+0000] {subprocess.py:93} INFO - socket.gaierror: [Errno -3] Temporary failure in name resolution
[2025-05-02T16:00:37.321+0000] {subprocess.py:93} INFO - 
[2025-05-02T16:00:37.322+0000] {subprocess.py:93} INFO - The above exception was the direct cause of the following exception:
[2025-05-02T16:00:37.323+0000] {subprocess.py:93} INFO - 
[2025-05-02T16:00:37.324+0000] {subprocess.py:93} INFO - Traceback (most recent call last):
[2025-05-02T16:00:37.324+0000] {subprocess.py:93} INFO -   File "/home/***/.local/lib/python3.12/site-packages/urllib3/connectionpool.py", line 793, in urlopen
[2025-05-02T16:00:37.325+0000] {subprocess.py:93} INFO -     response = self._make_request(
[2025-05-02T16:00:37.326+0000] {subprocess.py:93} INFO -                ^^^^^^^^^^^^^^^^^^^
[2025-05-02T16:00:37.326+0000] {subprocess.py:93} INFO -   File "/home/***/.local/lib/python3.12/site-packages/urllib3/connectionpool.py", line 496, in _make_request
[2025-05-02T16:00:37.327+0000] {subprocess.py:93} INFO -     conn.request(
[2025-05-02T16:00:37.328+0000] {subprocess.py:93} INFO -   File "/home/***/.local/lib/python3.12/site-packages/urllib3/connection.py", line 400, in request
[2025-05-02T16:00:37.329+0000] {subprocess.py:93} INFO -     self.endheaders()
[2025-05-02T16:00:37.329+0000] {subprocess.py:93} INFO -   File "/usr/local/lib/python3.12/http/client.py", line 1331, in endheaders
[2025-05-02T16:00:37.330+0000] {subprocess.py:93} INFO -     self._send_output(message_body, encode_chunked=encode_chunked)
[2025-05-02T16:00:37.331+0000] {subprocess.py:93} INFO -   File "/usr/local/lib/python3.12/http/client.py", line 1091, in _send_output
[2025-05-02T16:00:37.332+0000] {subprocess.py:93} INFO -     self.send(msg)
[2025-05-02T16:00:37.333+0000] {subprocess.py:93} INFO -   File "/usr/local/lib/python3.12/http/client.py", line 1035, in send
[2025-05-02T16:00:37.334+0000] {subprocess.py:93} INFO -     self.connect()
[2025-05-02T16:00:37.335+0000] {subprocess.py:93} INFO -   File "/home/***/.local/lib/python3.12/site-packages/urllib3/connection.py", line 238, in connect
[2025-05-02T16:00:37.337+0000] {subprocess.py:93} INFO -     self.sock = self._new_conn()
[2025-05-02T16:00:37.337+0000] {subprocess.py:93} INFO -                 ^^^^^^^^^^^^^^^^
[2025-05-02T16:00:37.338+0000] {subprocess.py:93} INFO -   File "/home/***/.local/lib/python3.12/site-packages/urllib3/connection.py", line 205, in _new_conn
[2025-05-02T16:00:37.338+0000] {subprocess.py:93} INFO -     raise NameResolutionError(self.host, self, e) from e
[2025-05-02T16:00:37.339+0000] {subprocess.py:93} INFO - urllib3.exceptions.NameResolutionError: <urllib3.connection.HTTPConnection object at 0x7f814e16a660>: Failed to resolve 'api.openweathermap.org' ([Errno -3] Temporary failure in name resolution)
[2025-05-02T16:00:37.339+0000] {subprocess.py:93} INFO - 
[2025-05-02T16:00:37.340+0000] {subprocess.py:93} INFO - The above exception was the direct cause of the following exception:
[2025-05-02T16:00:37.341+0000] {subprocess.py:93} INFO - 
[2025-05-02T16:00:37.342+0000] {subprocess.py:93} INFO - Traceback (most recent call last):
[2025-05-02T16:00:37.343+0000] {subprocess.py:93} INFO -   File "/home/***/.local/lib/python3.12/site-packages/requests/adapters.py", line 486, in send
[2025-05-02T16:00:37.344+0000] {subprocess.py:93} INFO -     resp = conn.urlopen(
[2025-05-02T16:00:37.345+0000] {subprocess.py:93} INFO -            ^^^^^^^^^^^^^
[2025-05-02T16:00:37.345+0000] {subprocess.py:93} INFO -   File "/home/***/.local/lib/python3.12/site-packages/urllib3/connectionpool.py", line 847, in urlopen
[2025-05-02T16:00:37.347+0000] {subprocess.py:93} INFO -     retries = retries.increment(
[2025-05-02T16:00:37.347+0000] {subprocess.py:93} INFO -               ^^^^^^^^^^^^^^^^^^
[2025-05-02T16:00:37.348+0000] {subprocess.py:93} INFO -   File "/home/***/.local/lib/python3.12/site-packages/urllib3/util/retry.py", line 515, in increment
[2025-05-02T16:00:37.348+0000] {subprocess.py:93} INFO -     raise MaxRetryError(_pool, url, reason) from reason  # type: ignore[arg-type]
[2025-05-02T16:00:37.349+0000] {subprocess.py:93} INFO -     ^^^^^^^^^^^^^^^^^^^^^^^^^^^^^^^^^^^^^^^^^^^^^^^^^^^
[2025-05-02T16:00:37.350+0000] {subprocess.py:93} INFO - urllib3.exceptions.MaxRetryError: HTTPConnectionPool(host='api.openweathermap.org', port=80): Max retries exceeded with url: /data/2.5/weather?q=Karachi&appid=65fd833bd0877ed9ae3333d9417463f0&units=metric (Caused by NameResolutionError("<urllib3.connection.HTTPConnection object at 0x7f814e16a660>: Failed to resolve 'api.openweathermap.org' ([Errno -3] Temporary failure in name resolution)"))
[2025-05-02T16:00:37.352+0000] {subprocess.py:93} INFO - 
[2025-05-02T16:00:37.353+0000] {subprocess.py:93} INFO - During handling of the above exception, another exception occurred:
[2025-05-02T16:00:37.353+0000] {subprocess.py:93} INFO - 
[2025-05-02T16:00:37.354+0000] {subprocess.py:93} INFO - Traceback (most recent call last):
[2025-05-02T16:00:37.354+0000] {subprocess.py:93} INFO -   File "/opt/***/scripts/collect_data.py", line 80, in <module>
[2025-05-02T16:00:37.355+0000] {subprocess.py:93} INFO -     collect_weather_data()
[2025-05-02T16:00:37.356+0000] {subprocess.py:93} INFO -   File "/opt/***/scripts/collect_data.py", line 41, in collect_weather_data
[2025-05-02T16:00:37.358+0000] {subprocess.py:93} INFO -     response = requests.get(URL)
[2025-05-02T16:00:37.359+0000] {subprocess.py:93} INFO -                ^^^^^^^^^^^^^^^^^
[2025-05-02T16:00:37.360+0000] {subprocess.py:93} INFO -   File "/home/***/.local/lib/python3.12/site-packages/requests/api.py", line 73, in get
[2025-05-02T16:00:37.360+0000] {subprocess.py:93} INFO -     return request("get", url, params=params, **kwargs)
[2025-05-02T16:00:37.361+0000] {subprocess.py:93} INFO -            ^^^^^^^^^^^^^^^^^^^^^^^^^^^^^^^^^^^^^^^^^^^^
[2025-05-02T16:00:37.361+0000] {subprocess.py:93} INFO -   File "/home/***/.local/lib/python3.12/site-packages/requests/api.py", line 59, in request
[2025-05-02T16:00:37.362+0000] {subprocess.py:93} INFO -     return session.request(method=method, url=url, **kwargs)
[2025-05-02T16:00:37.364+0000] {subprocess.py:93} INFO -            ^^^^^^^^^^^^^^^^^^^^^^^^^^^^^^^^^^^^^^^^^^^^^^^^^
[2025-05-02T16:00:37.365+0000] {subprocess.py:93} INFO -   File "/home/***/.local/lib/python3.12/site-packages/requests/sessions.py", line 589, in request
[2025-05-02T16:00:37.366+0000] {subprocess.py:93} INFO -     resp = self.send(prep, **send_kwargs)
[2025-05-02T16:00:37.367+0000] {subprocess.py:93} INFO -            ^^^^^^^^^^^^^^^^^^^^^^^^^^^^^^
[2025-05-02T16:00:37.367+0000] {subprocess.py:93} INFO -   File "/home/***/.local/lib/python3.12/site-packages/requests/sessions.py", line 703, in send
[2025-05-02T16:00:37.368+0000] {subprocess.py:93} INFO -     r = adapter.send(request, **kwargs)
[2025-05-02T16:00:37.369+0000] {subprocess.py:93} INFO -         ^^^^^^^^^^^^^^^^^^^^^^^^^^^^^^^
[2025-05-02T16:00:37.369+0000] {subprocess.py:93} INFO -   File "/home/***/.local/lib/python3.12/site-packages/requests/adapters.py", line 519, in send
[2025-05-02T16:00:37.370+0000] {subprocess.py:93} INFO -     raise ConnectionError(e, request=request)
[2025-05-02T16:00:37.371+0000] {subprocess.py:93} INFO - requests.exceptions.ConnectionError: HTTPConnectionPool(host='api.openweathermap.org', port=80): Max retries exceeded with url: /data/2.5/weather?q=Karachi&appid=65fd833bd0877ed9ae3333d9417463f0&units=metric (Caused by NameResolutionError("<urllib3.connection.HTTPConnection object at 0x7f814e16a660>: Failed to resolve 'api.openweathermap.org' ([Errno -3] Temporary failure in name resolution)"))
[2025-05-02T16:00:37.468+0000] {subprocess.py:97} INFO - Command exited with return code 1
[2025-05-02T16:00:37.481+0000] {taskinstance.py:441} INFO - ::group::Post task execution logs
[2025-05-02T16:00:40.291+0000] {taskinstance.py:2905} ERROR - Task failed with exception
Traceback (most recent call last):
  File "/home/airflow/.local/lib/python3.12/site-packages/airflow/models/taskinstance.py", line 465, in _execute_task
    result = _execute_callable(context=context, **execute_callable_kwargs)
             ^^^^^^^^^^^^^^^^^^^^^^^^^^^^^^^^^^^^^^^^^^^^^^^^^^^^^^^^^^^^^
  File "/home/airflow/.local/lib/python3.12/site-packages/airflow/models/taskinstance.py", line 432, in _execute_callable
    return execute_callable(context=context, **execute_callable_kwargs)
           ^^^^^^^^^^^^^^^^^^^^^^^^^^^^^^^^^^^^^^^^^^^^^^^^^^^^^^^^^^^^
  File "/home/airflow/.local/lib/python3.12/site-packages/airflow/models/baseoperator.py", line 400, in wrapper
    return func(self, *args, **kwargs)
           ^^^^^^^^^^^^^^^^^^^^^^^^^^^
  File "/home/airflow/.local/lib/python3.12/site-packages/airflow/operators/bash.py", line 243, in execute
    raise AirflowException(
airflow.exceptions.AirflowException: Bash command failed. The command returned a non-zero exit code 1.
[2025-05-02T16:00:40.315+0000] {taskinstance.py:1206} INFO - Marking task as FAILED. dag_id=weather_data_pipeline, task_id=collect_data, run_id=manual__2025-05-02T15:54:46.135169+00:00, execution_date=20250502T155446, start_date=20250502T160025, end_date=20250502T160040
[2025-05-02T16:00:40.338+0000] {standard_task_runner.py:110} ERROR - Failed to execute job 13 for task collect_data (Bash command failed. The command returned a non-zero exit code 1.; 251)
[2025-05-02T16:00:41.203+0000] {local_task_job_runner.py:240} INFO - Task exited with return code 1
[2025-05-02T16:00:42.024+0000] {taskinstance.py:3498} INFO - 0 downstream tasks scheduled from follow-on schedule check
[2025-05-02T16:00:42.036+0000] {local_task_job_runner.py:222} INFO - ::endgroup::
