[2025-05-02T16:06:01.531+0000] {local_task_job_runner.py:120} INFO - ::group::Pre task execution logs
[2025-05-02T16:06:01.682+0000] {taskinstance.py:2076} INFO - Dependencies all met for dep_context=non-requeueable deps ti=<TaskInstance: weather_data_pipeline.collect_data manual__2025-05-02T15:59:25.267930+00:00 [queued]>
[2025-05-02T16:06:01.723+0000] {taskinstance.py:2076} INFO - Dependencies all met for dep_context=requeueable deps ti=<TaskInstance: weather_data_pipeline.collect_data manual__2025-05-02T15:59:25.267930+00:00 [queued]>
[2025-05-02T16:06:01.726+0000] {taskinstance.py:2306} INFO - Starting attempt 1 of 1
[2025-05-02T16:06:01.786+0000] {taskinstance.py:2330} INFO - Executing <Task(BashOperator): collect_data> on 2025-05-02 15:59:25.267930+00:00
[2025-05-02T16:06:01.822+0000] {warnings.py:110} WARNING - /home/***/.local/lib/python3.12/site-packages/***/task/task_runner/standard_task_runner.py:61: DeprecationWarning: This process (pid=98) is multi-threaded, use of fork() may lead to deadlocks in the child.
  pid = os.fork()

[2025-05-02T16:06:01.827+0000] {standard_task_runner.py:63} INFO - Started process 102 to run task
[2025-05-02T16:06:01.832+0000] {standard_task_runner.py:90} INFO - Running: ['***', 'tasks', 'run', 'weather_data_pipeline', 'collect_data', 'manual__2025-05-02T15:59:25.267930+00:00', '--job-id', '51', '--raw', '--subdir', 'DAGS_FOLDER/weather_pipeline_dag.py', '--cfg-path', '/tmp/tmpkjvqpd7o']
[2025-05-02T16:06:01.840+0000] {standard_task_runner.py:91} INFO - Job 51: Subtask collect_data
[2025-05-02T16:06:01.997+0000] {task_command.py:426} INFO - Running <TaskInstance: weather_data_pipeline.collect_data manual__2025-05-02T15:59:25.267930+00:00 [running]> on host 8216558167cd
[2025-05-02T16:06:02.237+0000] {taskinstance.py:2648} INFO - Exporting env vars: AIRFLOW_CTX_DAG_OWNER='***' AIRFLOW_CTX_DAG_ID='weather_data_pipeline' AIRFLOW_CTX_TASK_ID='collect_data' AIRFLOW_CTX_EXECUTION_DATE='2025-05-02T15:59:25.267930+00:00' AIRFLOW_CTX_TRY_NUMBER='1' AIRFLOW_CTX_DAG_RUN_ID='manual__2025-05-02T15:59:25.267930+00:00'
[2025-05-02T16:06:02.242+0000] {taskinstance.py:430} INFO - ::endgroup::
[2025-05-02T16:06:02.248+0000] {subprocess.py:63} INFO - Tmp dir root location: /tmp
[2025-05-02T16:06:02.252+0000] {subprocess.py:75} INFO - Running command: ['/usr/bin/bash', '-c', 'python /opt/***/scripts/collect_data.py']
[2025-05-02T16:06:02.281+0000] {subprocess.py:86} INFO - Output:
[2025-05-02T16:06:29.346+0000] {subprocess.py:93} INFO - Traceback (most recent call last):
[2025-05-02T16:06:29.358+0000] {subprocess.py:93} INFO -   File "/home/***/.local/lib/python3.12/site-packages/urllib3/connection.py", line 198, in _new_conn
[2025-05-02T16:06:29.360+0000] {subprocess.py:93} INFO -     sock = connection.create_connection(
[2025-05-02T16:06:29.362+0000] {subprocess.py:93} INFO -            ^^^^^^^^^^^^^^^^^^^^^^^^^^^^^
[2025-05-02T16:06:29.363+0000] {subprocess.py:93} INFO -   File "/home/***/.local/lib/python3.12/site-packages/urllib3/util/connection.py", line 60, in create_connection
[2025-05-02T16:06:29.365+0000] {subprocess.py:93} INFO -     for res in socket.getaddrinfo(host, port, family, socket.SOCK_STREAM):
[2025-05-02T16:06:29.367+0000] {subprocess.py:93} INFO -                ^^^^^^^^^^^^^^^^^^^^^^^^^^^^^^^^^^^^^^^^^^^^^^^^^^^^^^^^^^
[2025-05-02T16:06:29.369+0000] {subprocess.py:93} INFO -   File "/usr/local/lib/python3.12/socket.py", line 963, in getaddrinfo
[2025-05-02T16:06:29.371+0000] {subprocess.py:93} INFO -     for res in _socket.getaddrinfo(host, port, family, type, proto, flags):
[2025-05-02T16:06:29.372+0000] {subprocess.py:93} INFO -                ^^^^^^^^^^^^^^^^^^^^^^^^^^^^^^^^^^^^^^^^^^^^^^^^^^^^^^^^^^^
[2025-05-02T16:06:29.374+0000] {subprocess.py:93} INFO - socket.gaierror: [Errno -3] Temporary failure in name resolution
[2025-05-02T16:06:29.377+0000] {subprocess.py:93} INFO - 
[2025-05-02T16:06:29.379+0000] {subprocess.py:93} INFO - The above exception was the direct cause of the following exception:
[2025-05-02T16:06:29.381+0000] {subprocess.py:93} INFO - 
[2025-05-02T16:06:29.382+0000] {subprocess.py:93} INFO - Traceback (most recent call last):
[2025-05-02T16:06:29.384+0000] {subprocess.py:93} INFO -   File "/home/***/.local/lib/python3.12/site-packages/urllib3/connectionpool.py", line 793, in urlopen
[2025-05-02T16:06:29.386+0000] {subprocess.py:93} INFO -     response = self._make_request(
[2025-05-02T16:06:29.387+0000] {subprocess.py:93} INFO -                ^^^^^^^^^^^^^^^^^^^
[2025-05-02T16:06:29.389+0000] {subprocess.py:93} INFO -   File "/home/***/.local/lib/python3.12/site-packages/urllib3/connectionpool.py", line 496, in _make_request
[2025-05-02T16:06:29.390+0000] {subprocess.py:93} INFO -     conn.request(
[2025-05-02T16:06:29.392+0000] {subprocess.py:93} INFO -   File "/home/***/.local/lib/python3.12/site-packages/urllib3/connection.py", line 400, in request
[2025-05-02T16:06:29.394+0000] {subprocess.py:93} INFO -     self.endheaders()
[2025-05-02T16:06:29.395+0000] {subprocess.py:93} INFO -   File "/usr/local/lib/python3.12/http/client.py", line 1331, in endheaders
[2025-05-02T16:06:29.397+0000] {subprocess.py:93} INFO -     self._send_output(message_body, encode_chunked=encode_chunked)
[2025-05-02T16:06:29.398+0000] {subprocess.py:93} INFO -   File "/usr/local/lib/python3.12/http/client.py", line 1091, in _send_output
[2025-05-02T16:06:29.400+0000] {subprocess.py:93} INFO -     self.send(msg)
[2025-05-02T16:06:29.402+0000] {subprocess.py:93} INFO -   File "/usr/local/lib/python3.12/http/client.py", line 1035, in send
[2025-05-02T16:06:29.404+0000] {subprocess.py:93} INFO -     self.connect()
[2025-05-02T16:06:29.406+0000] {subprocess.py:93} INFO -   File "/home/***/.local/lib/python3.12/site-packages/urllib3/connection.py", line 238, in connect
[2025-05-02T16:06:29.408+0000] {subprocess.py:93} INFO -     self.sock = self._new_conn()
[2025-05-02T16:06:29.409+0000] {subprocess.py:93} INFO -                 ^^^^^^^^^^^^^^^^
[2025-05-02T16:06:29.411+0000] {subprocess.py:93} INFO -   File "/home/***/.local/lib/python3.12/site-packages/urllib3/connection.py", line 205, in _new_conn
[2025-05-02T16:06:29.412+0000] {subprocess.py:93} INFO -     raise NameResolutionError(self.host, self, e) from e
[2025-05-02T16:06:29.414+0000] {subprocess.py:93} INFO - urllib3.exceptions.NameResolutionError: <urllib3.connection.HTTPConnection object at 0x7f67138bd1f0>: Failed to resolve 'api.openweathermap.org' ([Errno -3] Temporary failure in name resolution)
[2025-05-02T16:06:29.415+0000] {subprocess.py:93} INFO - 
[2025-05-02T16:06:29.417+0000] {subprocess.py:93} INFO - The above exception was the direct cause of the following exception:
[2025-05-02T16:06:29.419+0000] {subprocess.py:93} INFO - 
[2025-05-02T16:06:29.420+0000] {subprocess.py:93} INFO - Traceback (most recent call last):
[2025-05-02T16:06:29.421+0000] {subprocess.py:93} INFO -   File "/home/***/.local/lib/python3.12/site-packages/requests/adapters.py", line 486, in send
[2025-05-02T16:06:29.423+0000] {subprocess.py:93} INFO -     resp = conn.urlopen(
[2025-05-02T16:06:29.425+0000] {subprocess.py:93} INFO -            ^^^^^^^^^^^^^
[2025-05-02T16:06:29.427+0000] {subprocess.py:93} INFO -   File "/home/***/.local/lib/python3.12/site-packages/urllib3/connectionpool.py", line 847, in urlopen
[2025-05-02T16:06:29.430+0000] {subprocess.py:93} INFO -     retries = retries.increment(
[2025-05-02T16:06:29.431+0000] {subprocess.py:93} INFO -               ^^^^^^^^^^^^^^^^^^
[2025-05-02T16:06:29.433+0000] {subprocess.py:93} INFO -   File "/home/***/.local/lib/python3.12/site-packages/urllib3/util/retry.py", line 515, in increment
[2025-05-02T16:06:29.434+0000] {subprocess.py:93} INFO -     raise MaxRetryError(_pool, url, reason) from reason  # type: ignore[arg-type]
[2025-05-02T16:06:29.436+0000] {subprocess.py:93} INFO -     ^^^^^^^^^^^^^^^^^^^^^^^^^^^^^^^^^^^^^^^^^^^^^^^^^^^
[2025-05-02T16:06:29.437+0000] {subprocess.py:93} INFO - urllib3.exceptions.MaxRetryError: HTTPConnectionPool(host='api.openweathermap.org', port=80): Max retries exceeded with url: /data/2.5/weather?q=Karachi&appid=65fd833bd0877ed9ae3333d9417463f0&units=metric (Caused by NameResolutionError("<urllib3.connection.HTTPConnection object at 0x7f67138bd1f0>: Failed to resolve 'api.openweathermap.org' ([Errno -3] Temporary failure in name resolution)"))
[2025-05-02T16:06:29.438+0000] {subprocess.py:93} INFO - 
[2025-05-02T16:06:29.439+0000] {subprocess.py:93} INFO - During handling of the above exception, another exception occurred:
[2025-05-02T16:06:29.441+0000] {subprocess.py:93} INFO - 
[2025-05-02T16:06:29.443+0000] {subprocess.py:93} INFO - Traceback (most recent call last):
[2025-05-02T16:06:29.445+0000] {subprocess.py:93} INFO -   File "/opt/***/scripts/collect_data.py", line 80, in <module>
[2025-05-02T16:06:29.447+0000] {subprocess.py:93} INFO -     collect_weather_data()
[2025-05-02T16:06:29.449+0000] {subprocess.py:93} INFO -   File "/opt/***/scripts/collect_data.py", line 41, in collect_weather_data
[2025-05-02T16:06:29.450+0000] {subprocess.py:93} INFO -     response = requests.get(URL)
[2025-05-02T16:06:29.452+0000] {subprocess.py:93} INFO -                ^^^^^^^^^^^^^^^^^
[2025-05-02T16:06:29.453+0000] {subprocess.py:93} INFO -   File "/home/***/.local/lib/python3.12/site-packages/requests/api.py", line 73, in get
[2025-05-02T16:06:29.454+0000] {subprocess.py:93} INFO -     return request("get", url, params=params, **kwargs)
[2025-05-02T16:06:29.457+0000] {subprocess.py:93} INFO -            ^^^^^^^^^^^^^^^^^^^^^^^^^^^^^^^^^^^^^^^^^^^^
[2025-05-02T16:06:29.458+0000] {subprocess.py:93} INFO -   File "/home/***/.local/lib/python3.12/site-packages/requests/api.py", line 59, in request
[2025-05-02T16:06:29.460+0000] {subprocess.py:93} INFO -     return session.request(method=method, url=url, **kwargs)
[2025-05-02T16:06:29.462+0000] {subprocess.py:93} INFO -            ^^^^^^^^^^^^^^^^^^^^^^^^^^^^^^^^^^^^^^^^^^^^^^^^^
[2025-05-02T16:06:29.464+0000] {subprocess.py:93} INFO -   File "/home/***/.local/lib/python3.12/site-packages/requests/sessions.py", line 589, in request
[2025-05-02T16:06:29.467+0000] {subprocess.py:93} INFO -     resp = self.send(prep, **send_kwargs)
[2025-05-02T16:06:29.468+0000] {subprocess.py:93} INFO -            ^^^^^^^^^^^^^^^^^^^^^^^^^^^^^^
[2025-05-02T16:06:29.470+0000] {subprocess.py:93} INFO -   File "/home/***/.local/lib/python3.12/site-packages/requests/sessions.py", line 703, in send
[2025-05-02T16:06:29.472+0000] {subprocess.py:93} INFO -     r = adapter.send(request, **kwargs)
[2025-05-02T16:06:29.473+0000] {subprocess.py:93} INFO -         ^^^^^^^^^^^^^^^^^^^^^^^^^^^^^^^
[2025-05-02T16:06:29.475+0000] {subprocess.py:93} INFO -   File "/home/***/.local/lib/python3.12/site-packages/requests/adapters.py", line 519, in send
[2025-05-02T16:06:29.476+0000] {subprocess.py:93} INFO -     raise ConnectionError(e, request=request)
[2025-05-02T16:06:29.478+0000] {subprocess.py:93} INFO - requests.exceptions.ConnectionError: HTTPConnectionPool(host='api.openweathermap.org', port=80): Max retries exceeded with url: /data/2.5/weather?q=Karachi&appid=65fd833bd0877ed9ae3333d9417463f0&units=metric (Caused by NameResolutionError("<urllib3.connection.HTTPConnection object at 0x7f67138bd1f0>: Failed to resolve 'api.openweathermap.org' ([Errno -3] Temporary failure in name resolution)"))
[2025-05-02T16:06:29.533+0000] {subprocess.py:97} INFO - Command exited with return code 1
[2025-05-02T16:06:29.539+0000] {taskinstance.py:441} INFO - ::group::Post task execution logs
[2025-05-02T16:06:29.916+0000] {taskinstance.py:2905} ERROR - Task failed with exception
Traceback (most recent call last):
  File "/home/airflow/.local/lib/python3.12/site-packages/airflow/models/taskinstance.py", line 465, in _execute_task
    result = _execute_callable(context=context, **execute_callable_kwargs)
             ^^^^^^^^^^^^^^^^^^^^^^^^^^^^^^^^^^^^^^^^^^^^^^^^^^^^^^^^^^^^^
  File "/home/airflow/.local/lib/python3.12/site-packages/airflow/models/taskinstance.py", line 432, in _execute_callable
    return execute_callable(context=context, **execute_callable_kwargs)
           ^^^^^^^^^^^^^^^^^^^^^^^^^^^^^^^^^^^^^^^^^^^^^^^^^^^^^^^^^^^^
  File "/home/airflow/.local/lib/python3.12/site-packages/airflow/models/baseoperator.py", line 400, in wrapper
    return func(self, *args, **kwargs)
           ^^^^^^^^^^^^^^^^^^^^^^^^^^^
  File "/home/airflow/.local/lib/python3.12/site-packages/airflow/operators/bash.py", line 243, in execute
    raise AirflowException(
airflow.exceptions.AirflowException: Bash command failed. The command returned a non-zero exit code 1.
[2025-05-02T16:06:29.948+0000] {taskinstance.py:1206} INFO - Marking task as FAILED. dag_id=weather_data_pipeline, task_id=collect_data, run_id=manual__2025-05-02T15:59:25.267930+00:00, execution_date=20250502T155925, start_date=20250502T160601, end_date=20250502T160629
[2025-05-02T16:06:30.009+0000] {standard_task_runner.py:110} ERROR - Failed to execute job 51 for task collect_data (Bash command failed. The command returned a non-zero exit code 1.; 102)
[2025-05-02T16:06:30.084+0000] {local_task_job_runner.py:240} INFO - Task exited with return code 1
[2025-05-02T16:06:30.172+0000] {taskinstance.py:3498} INFO - 0 downstream tasks scheduled from follow-on schedule check
[2025-05-02T16:06:30.183+0000] {local_task_job_runner.py:222} INFO - ::endgroup::
