[2025-05-02T16:04:21.077+0000] {local_task_job_runner.py:120} INFO - ::group::Pre task execution logs
[2025-05-02T16:04:21.146+0000] {taskinstance.py:2076} INFO - Dependencies all met for dep_context=non-requeueable deps ti=<TaskInstance: weather_data_pipeline.collect_data manual__2025-05-02T16:04:12.861643+00:00 [queued]>
[2025-05-02T16:04:21.170+0000] {taskinstance.py:2076} INFO - Dependencies all met for dep_context=requeueable deps ti=<TaskInstance: weather_data_pipeline.collect_data manual__2025-05-02T16:04:12.861643+00:00 [queued]>
[2025-05-02T16:04:21.172+0000] {taskinstance.py:2306} INFO - Starting attempt 1 of 1
[2025-05-02T16:04:21.209+0000] {taskinstance.py:2330} INFO - Executing <Task(BashOperator): collect_data> on 2025-05-02 16:04:12.861643+00:00
[2025-05-02T16:04:21.226+0000] {warnings.py:110} WARNING - /home/***/.local/lib/python3.12/site-packages/***/task/task_runner/standard_task_runner.py:61: DeprecationWarning: This process (pid=75) is multi-threaded, use of fork() may lead to deadlocks in the child.
  pid = os.fork()

[2025-05-02T16:04:21.228+0000] {standard_task_runner.py:63} INFO - Started process 77 to run task
[2025-05-02T16:04:21.230+0000] {standard_task_runner.py:90} INFO - Running: ['***', 'tasks', 'run', 'weather_data_pipeline', 'collect_data', 'manual__2025-05-02T16:04:12.861643+00:00', '--job-id', '49', '--raw', '--subdir', 'DAGS_FOLDER/weather_pipeline_dag.py', '--cfg-path', '/tmp/tmp5eqb5mm_']
[2025-05-02T16:04:21.236+0000] {standard_task_runner.py:91} INFO - Job 49: Subtask collect_data
[2025-05-02T16:04:21.364+0000] {task_command.py:426} INFO - Running <TaskInstance: weather_data_pipeline.collect_data manual__2025-05-02T16:04:12.861643+00:00 [running]> on host 8216558167cd
[2025-05-02T16:04:21.600+0000] {taskinstance.py:2648} INFO - Exporting env vars: AIRFLOW_CTX_DAG_OWNER='***' AIRFLOW_CTX_DAG_ID='weather_data_pipeline' AIRFLOW_CTX_TASK_ID='collect_data' AIRFLOW_CTX_EXECUTION_DATE='2025-05-02T16:04:12.861643+00:00' AIRFLOW_CTX_TRY_NUMBER='1' AIRFLOW_CTX_DAG_RUN_ID='manual__2025-05-02T16:04:12.861643+00:00'
[2025-05-02T16:04:21.609+0000] {taskinstance.py:430} INFO - ::endgroup::
[2025-05-02T16:04:21.629+0000] {subprocess.py:63} INFO - Tmp dir root location: /tmp
[2025-05-02T16:04:21.631+0000] {subprocess.py:75} INFO - Running command: ['/usr/bin/bash', '-c', 'python /opt/***/scripts/collect_data.py']
[2025-05-02T16:04:21.657+0000] {subprocess.py:86} INFO - Output:
[2025-05-02T16:04:33.110+0000] {subprocess.py:93} INFO - Traceback (most recent call last):
[2025-05-02T16:04:33.123+0000] {subprocess.py:93} INFO -   File "/home/***/.local/lib/python3.12/site-packages/urllib3/connection.py", line 198, in _new_conn
[2025-05-02T16:04:33.197+0000] {subprocess.py:93} INFO -     sock = connection.create_connection(
[2025-05-02T16:04:33.250+0000] {subprocess.py:93} INFO -            ^^^^^^^^^^^^^^^^^^^^^^^^^^^^^
[2025-05-02T16:04:33.268+0000] {subprocess.py:93} INFO -   File "/home/***/.local/lib/python3.12/site-packages/urllib3/util/connection.py", line 60, in create_connection
[2025-05-02T16:04:33.347+0000] {subprocess.py:93} INFO -     for res in socket.getaddrinfo(host, port, family, socket.SOCK_STREAM):
[2025-05-02T16:04:33.360+0000] {subprocess.py:93} INFO -                ^^^^^^^^^^^^^^^^^^^^^^^^^^^^^^^^^^^^^^^^^^^^^^^^^^^^^^^^^^
[2025-05-02T16:04:33.361+0000] {subprocess.py:93} INFO -   File "/usr/local/lib/python3.12/socket.py", line 963, in getaddrinfo
[2025-05-02T16:04:33.362+0000] {subprocess.py:93} INFO -     for res in _socket.getaddrinfo(host, port, family, type, proto, flags):
[2025-05-02T16:04:33.363+0000] {subprocess.py:93} INFO -                ^^^^^^^^^^^^^^^^^^^^^^^^^^^^^^^^^^^^^^^^^^^^^^^^^^^^^^^^^^^
[2025-05-02T16:04:33.363+0000] {subprocess.py:93} INFO - socket.gaierror: [Errno -3] Temporary failure in name resolution
[2025-05-02T16:04:33.364+0000] {subprocess.py:93} INFO - 
[2025-05-02T16:04:33.365+0000] {subprocess.py:93} INFO - The above exception was the direct cause of the following exception:
[2025-05-02T16:04:33.366+0000] {subprocess.py:93} INFO - 
[2025-05-02T16:04:33.367+0000] {subprocess.py:93} INFO - Traceback (most recent call last):
[2025-05-02T16:04:33.368+0000] {subprocess.py:93} INFO -   File "/home/***/.local/lib/python3.12/site-packages/urllib3/connectionpool.py", line 793, in urlopen
[2025-05-02T16:04:33.371+0000] {subprocess.py:93} INFO -     response = self._make_request(
[2025-05-02T16:04:33.372+0000] {subprocess.py:93} INFO -                ^^^^^^^^^^^^^^^^^^^
[2025-05-02T16:04:33.373+0000] {subprocess.py:93} INFO -   File "/home/***/.local/lib/python3.12/site-packages/urllib3/connectionpool.py", line 496, in _make_request
[2025-05-02T16:04:33.375+0000] {subprocess.py:93} INFO -     conn.request(
[2025-05-02T16:04:33.376+0000] {subprocess.py:93} INFO -   File "/home/***/.local/lib/python3.12/site-packages/urllib3/connection.py", line 400, in request
[2025-05-02T16:04:33.377+0000] {subprocess.py:93} INFO -     self.endheaders()
[2025-05-02T16:04:33.378+0000] {subprocess.py:93} INFO -   File "/usr/local/lib/python3.12/http/client.py", line 1331, in endheaders
[2025-05-02T16:04:33.379+0000] {subprocess.py:93} INFO -     self._send_output(message_body, encode_chunked=encode_chunked)
[2025-05-02T16:04:33.380+0000] {subprocess.py:93} INFO -   File "/usr/local/lib/python3.12/http/client.py", line 1091, in _send_output
[2025-05-02T16:04:33.381+0000] {subprocess.py:93} INFO -     self.send(msg)
[2025-05-02T16:04:33.382+0000] {subprocess.py:93} INFO -   File "/usr/local/lib/python3.12/http/client.py", line 1035, in send
[2025-05-02T16:04:33.383+0000] {subprocess.py:93} INFO -     self.connect()
[2025-05-02T16:04:33.385+0000] {subprocess.py:93} INFO -   File "/home/***/.local/lib/python3.12/site-packages/urllib3/connection.py", line 238, in connect
[2025-05-02T16:04:33.386+0000] {subprocess.py:93} INFO -     self.sock = self._new_conn()
[2025-05-02T16:04:33.388+0000] {subprocess.py:93} INFO -                 ^^^^^^^^^^^^^^^^
[2025-05-02T16:04:33.389+0000] {subprocess.py:93} INFO -   File "/home/***/.local/lib/python3.12/site-packages/urllib3/connection.py", line 205, in _new_conn
[2025-05-02T16:04:33.390+0000] {subprocess.py:93} INFO -     raise NameResolutionError(self.host, self, e) from e
[2025-05-02T16:04:33.391+0000] {subprocess.py:93} INFO - urllib3.exceptions.NameResolutionError: <urllib3.connection.HTTPConnection object at 0x7fc374320b00>: Failed to resolve 'api.openweathermap.org' ([Errno -3] Temporary failure in name resolution)
[2025-05-02T16:04:33.392+0000] {subprocess.py:93} INFO - 
[2025-05-02T16:04:33.393+0000] {subprocess.py:93} INFO - The above exception was the direct cause of the following exception:
[2025-05-02T16:04:33.394+0000] {subprocess.py:93} INFO - 
[2025-05-02T16:04:33.394+0000] {subprocess.py:93} INFO - Traceback (most recent call last):
[2025-05-02T16:04:33.395+0000] {subprocess.py:93} INFO -   File "/home/***/.local/lib/python3.12/site-packages/requests/adapters.py", line 486, in send
[2025-05-02T16:04:33.397+0000] {subprocess.py:93} INFO -     resp = conn.urlopen(
[2025-05-02T16:04:33.399+0000] {subprocess.py:93} INFO -            ^^^^^^^^^^^^^
[2025-05-02T16:04:33.400+0000] {subprocess.py:93} INFO -   File "/home/***/.local/lib/python3.12/site-packages/urllib3/connectionpool.py", line 847, in urlopen
[2025-05-02T16:04:33.401+0000] {subprocess.py:93} INFO -     retries = retries.increment(
[2025-05-02T16:04:33.402+0000] {subprocess.py:93} INFO -               ^^^^^^^^^^^^^^^^^^
[2025-05-02T16:04:33.404+0000] {subprocess.py:93} INFO -   File "/home/***/.local/lib/python3.12/site-packages/urllib3/util/retry.py", line 515, in increment
[2025-05-02T16:04:33.405+0000] {subprocess.py:93} INFO -     raise MaxRetryError(_pool, url, reason) from reason  # type: ignore[arg-type]
[2025-05-02T16:04:33.407+0000] {subprocess.py:93} INFO -     ^^^^^^^^^^^^^^^^^^^^^^^^^^^^^^^^^^^^^^^^^^^^^^^^^^^
[2025-05-02T16:04:33.408+0000] {subprocess.py:93} INFO - urllib3.exceptions.MaxRetryError: HTTPConnectionPool(host='api.openweathermap.org', port=80): Max retries exceeded with url: /data/2.5/weather?q=Karachi&appid=65fd833bd0877ed9ae3333d9417463f0&units=metric (Caused by NameResolutionError("<urllib3.connection.HTTPConnection object at 0x7fc374320b00>: Failed to resolve 'api.openweathermap.org' ([Errno -3] Temporary failure in name resolution)"))
[2025-05-02T16:04:33.411+0000] {subprocess.py:93} INFO - 
[2025-05-02T16:04:33.412+0000] {subprocess.py:93} INFO - During handling of the above exception, another exception occurred:
[2025-05-02T16:04:33.414+0000] {subprocess.py:93} INFO - 
[2025-05-02T16:04:33.415+0000] {subprocess.py:93} INFO - Traceback (most recent call last):
[2025-05-02T16:04:33.416+0000] {subprocess.py:93} INFO -   File "/opt/***/scripts/collect_data.py", line 80, in <module>
[2025-05-02T16:04:33.477+0000] {subprocess.py:93} INFO -     collect_weather_data()
[2025-05-02T16:04:33.483+0000] {subprocess.py:93} INFO -   File "/opt/***/scripts/collect_data.py", line 41, in collect_weather_data
[2025-05-02T16:04:33.485+0000] {subprocess.py:93} INFO -     response = requests.get(URL)
[2025-05-02T16:04:33.486+0000] {subprocess.py:93} INFO -                ^^^^^^^^^^^^^^^^^
[2025-05-02T16:04:33.487+0000] {subprocess.py:93} INFO -   File "/home/***/.local/lib/python3.12/site-packages/requests/api.py", line 73, in get
[2025-05-02T16:04:33.489+0000] {subprocess.py:93} INFO -     return request("get", url, params=params, **kwargs)
[2025-05-02T16:04:33.491+0000] {subprocess.py:93} INFO -            ^^^^^^^^^^^^^^^^^^^^^^^^^^^^^^^^^^^^^^^^^^^^
[2025-05-02T16:04:33.492+0000] {subprocess.py:93} INFO -   File "/home/***/.local/lib/python3.12/site-packages/requests/api.py", line 59, in request
[2025-05-02T16:04:33.494+0000] {subprocess.py:93} INFO -     return session.request(method=method, url=url, **kwargs)
[2025-05-02T16:04:33.495+0000] {subprocess.py:93} INFO -            ^^^^^^^^^^^^^^^^^^^^^^^^^^^^^^^^^^^^^^^^^^^^^^^^^
[2025-05-02T16:04:33.497+0000] {subprocess.py:93} INFO -   File "/home/***/.local/lib/python3.12/site-packages/requests/sessions.py", line 589, in request
[2025-05-02T16:04:33.499+0000] {subprocess.py:93} INFO -     resp = self.send(prep, **send_kwargs)
[2025-05-02T16:04:33.502+0000] {subprocess.py:93} INFO -            ^^^^^^^^^^^^^^^^^^^^^^^^^^^^^^
[2025-05-02T16:04:33.505+0000] {subprocess.py:93} INFO -   File "/home/***/.local/lib/python3.12/site-packages/requests/sessions.py", line 703, in send
[2025-05-02T16:04:33.507+0000] {subprocess.py:93} INFO -     r = adapter.send(request, **kwargs)
[2025-05-02T16:04:33.509+0000] {subprocess.py:93} INFO -         ^^^^^^^^^^^^^^^^^^^^^^^^^^^^^^^
[2025-05-02T16:04:33.510+0000] {subprocess.py:93} INFO -   File "/home/***/.local/lib/python3.12/site-packages/requests/adapters.py", line 519, in send
[2025-05-02T16:04:33.512+0000] {subprocess.py:93} INFO -     raise ConnectionError(e, request=request)
[2025-05-02T16:04:33.513+0000] {subprocess.py:93} INFO - requests.exceptions.ConnectionError: HTTPConnectionPool(host='api.openweathermap.org', port=80): Max retries exceeded with url: /data/2.5/weather?q=Karachi&appid=65fd833bd0877ed9ae3333d9417463f0&units=metric (Caused by NameResolutionError("<urllib3.connection.HTTPConnection object at 0x7fc374320b00>: Failed to resolve 'api.openweathermap.org' ([Errno -3] Temporary failure in name resolution)"))
[2025-05-02T16:04:33.735+0000] {subprocess.py:97} INFO - Command exited with return code 1
[2025-05-02T16:04:33.762+0000] {taskinstance.py:441} INFO - ::group::Post task execution logs
[2025-05-02T16:04:46.129+0000] {taskinstance.py:2905} ERROR - Task failed with exception
Traceback (most recent call last):
  File "/home/airflow/.local/lib/python3.12/site-packages/airflow/models/taskinstance.py", line 465, in _execute_task
    result = _execute_callable(context=context, **execute_callable_kwargs)
             ^^^^^^^^^^^^^^^^^^^^^^^^^^^^^^^^^^^^^^^^^^^^^^^^^^^^^^^^^^^^^
  File "/home/airflow/.local/lib/python3.12/site-packages/airflow/models/taskinstance.py", line 432, in _execute_callable
    return execute_callable(context=context, **execute_callable_kwargs)
           ^^^^^^^^^^^^^^^^^^^^^^^^^^^^^^^^^^^^^^^^^^^^^^^^^^^^^^^^^^^^
  File "/home/airflow/.local/lib/python3.12/site-packages/airflow/models/baseoperator.py", line 400, in wrapper
    return func(self, *args, **kwargs)
           ^^^^^^^^^^^^^^^^^^^^^^^^^^^
  File "/home/airflow/.local/lib/python3.12/site-packages/airflow/operators/bash.py", line 243, in execute
    raise AirflowException(
airflow.exceptions.AirflowException: Bash command failed. The command returned a non-zero exit code 1.
[2025-05-02T16:04:46.194+0000] {taskinstance.py:1206} INFO - Marking task as FAILED. dag_id=weather_data_pipeline, task_id=collect_data, run_id=manual__2025-05-02T16:04:12.861643+00:00, execution_date=20250502T160412, start_date=20250502T160421, end_date=20250502T160446
[2025-05-02T16:04:46.265+0000] {standard_task_runner.py:110} ERROR - Failed to execute job 49 for task collect_data (Bash command failed. The command returned a non-zero exit code 1.; 77)
[2025-05-02T16:04:46.323+0000] {local_task_job_runner.py:240} INFO - Task exited with return code 1
[2025-05-02T16:04:46.392+0000] {taskinstance.py:3498} INFO - 0 downstream tasks scheduled from follow-on schedule check
[2025-05-02T16:04:46.404+0000] {local_task_job_runner.py:222} INFO - ::endgroup::
