[2025-05-02T16:05:59.578+0000] {task_context_logger.py:104} ERROR - Executor reports task instance <TaskInstance: weather_data_pipeline.preprocess_data manual__2025-05-02T16:04:12.861643+00:00 [queued]> finished (failed) although the task says it's queued. (Info: None) Was the task killed externally?
