[2025-05-02T16:06:35.505+0000] {local_task_job_runner.py:120} INFO - ::group::Pre task execution logs
[2025-05-02T16:06:35.534+0000] {taskinstance.py:2076} INFO - Dependencies all met for dep_context=non-requeueable deps ti=<TaskInstance: weather_data_pipeline.preprocess_data manual__2025-05-02T16:05:59.217154+00:00 [queued]>
[2025-05-02T16:06:35.548+0000] {taskinstance.py:2076} INFO - Dependencies all met for dep_context=requeueable deps ti=<TaskInstance: weather_data_pipeline.preprocess_data manual__2025-05-02T16:05:59.217154+00:00 [queued]>
[2025-05-02T16:06:35.549+0000] {taskinstance.py:2306} INFO - Starting attempt 1 of 1
[2025-05-02T16:06:35.566+0000] {taskinstance.py:2330} INFO - Executing <Task(BashOperator): preprocess_data> on 2025-05-02 16:05:59.217154+00:00
[2025-05-02T16:06:35.576+0000] {warnings.py:110} WARNING - /home/***/.local/lib/python3.12/site-packages/***/task/task_runner/standard_task_runner.py:61: DeprecationWarning: This process (pid=114) is multi-threaded, use of fork() may lead to deadlocks in the child.
  pid = os.fork()

[2025-05-02T16:06:35.579+0000] {standard_task_runner.py:63} INFO - Started process 116 to run task
[2025-05-02T16:06:35.578+0000] {standard_task_runner.py:90} INFO - Running: ['***', 'tasks', 'run', 'weather_data_pipeline', 'preprocess_data', 'manual__2025-05-02T16:05:59.217154+00:00', '--job-id', '53', '--raw', '--subdir', 'DAGS_FOLDER/weather_pipeline_dag.py', '--cfg-path', '/tmp/tmp6tskf53d']
[2025-05-02T16:06:35.582+0000] {standard_task_runner.py:91} INFO - Job 53: Subtask preprocess_data
[2025-05-02T16:06:35.653+0000] {task_command.py:426} INFO - Running <TaskInstance: weather_data_pipeline.preprocess_data manual__2025-05-02T16:05:59.217154+00:00 [running]> on host 8216558167cd
[2025-05-02T16:06:35.818+0000] {taskinstance.py:2648} INFO - Exporting env vars: AIRFLOW_CTX_DAG_OWNER='***' AIRFLOW_CTX_DAG_ID='weather_data_pipeline' AIRFLOW_CTX_TASK_ID='preprocess_data' AIRFLOW_CTX_EXECUTION_DATE='2025-05-02T16:05:59.217154+00:00' AIRFLOW_CTX_TRY_NUMBER='1' AIRFLOW_CTX_DAG_RUN_ID='manual__2025-05-02T16:05:59.217154+00:00'
[2025-05-02T16:06:35.823+0000] {taskinstance.py:430} INFO - ::endgroup::
[2025-05-02T16:06:35.828+0000] {subprocess.py:63} INFO - Tmp dir root location: /tmp
[2025-05-02T16:06:35.831+0000] {subprocess.py:75} INFO - Running command: ['/usr/bin/bash', '-c', 'python /opt/***/scripts/preprocess_data.py']
[2025-05-02T16:06:35.857+0000] {subprocess.py:86} INFO - Output:
[2025-05-02T16:06:36.958+0000] {subprocess.py:93} INFO - Traceback (most recent call last):
[2025-05-02T16:06:36.959+0000] {subprocess.py:93} INFO -   File "/opt/***/scripts/preprocess_data.py", line 13, in <module>
[2025-05-02T16:06:36.962+0000] {subprocess.py:93} INFO -     from sklearn.preprocessing import StandardScaler
[2025-05-02T16:06:36.962+0000] {subprocess.py:93} INFO - ModuleNotFoundError: No module named 'sklearn'
[2025-05-02T16:06:37.101+0000] {subprocess.py:97} INFO - Command exited with return code 1
[2025-05-02T16:06:37.103+0000] {taskinstance.py:441} INFO - ::group::Post task execution logs
[2025-05-02T16:06:37.118+0000] {taskinstance.py:2905} ERROR - Task failed with exception
Traceback (most recent call last):
  File "/home/airflow/.local/lib/python3.12/site-packages/airflow/models/taskinstance.py", line 465, in _execute_task
    result = _execute_callable(context=context, **execute_callable_kwargs)
             ^^^^^^^^^^^^^^^^^^^^^^^^^^^^^^^^^^^^^^^^^^^^^^^^^^^^^^^^^^^^^
  File "/home/airflow/.local/lib/python3.12/site-packages/airflow/models/taskinstance.py", line 432, in _execute_callable
    return execute_callable(context=context, **execute_callable_kwargs)
           ^^^^^^^^^^^^^^^^^^^^^^^^^^^^^^^^^^^^^^^^^^^^^^^^^^^^^^^^^^^^
  File "/home/airflow/.local/lib/python3.12/site-packages/airflow/models/baseoperator.py", line 400, in wrapper
    return func(self, *args, **kwargs)
           ^^^^^^^^^^^^^^^^^^^^^^^^^^^
  File "/home/airflow/.local/lib/python3.12/site-packages/airflow/operators/bash.py", line 243, in execute
    raise AirflowException(
airflow.exceptions.AirflowException: Bash command failed. The command returned a non-zero exit code 1.
[2025-05-02T16:06:37.129+0000] {taskinstance.py:1206} INFO - Marking task as FAILED. dag_id=weather_data_pipeline, task_id=preprocess_data, run_id=manual__2025-05-02T16:05:59.217154+00:00, execution_date=20250502T160559, start_date=20250502T160635, end_date=20250502T160637
[2025-05-02T16:06:37.149+0000] {standard_task_runner.py:110} ERROR - Failed to execute job 53 for task preprocess_data (Bash command failed. The command returned a non-zero exit code 1.; 116)
[2025-05-02T16:06:37.164+0000] {local_task_job_runner.py:240} INFO - Task exited with return code 1
[2025-05-02T16:06:37.186+0000] {taskinstance.py:3498} INFO - 0 downstream tasks scheduled from follow-on schedule check
[2025-05-02T16:06:37.190+0000] {local_task_job_runner.py:222} INFO - ::endgroup::
