[2025-05-02T15:38:13.611+0000] {local_task_job_runner.py:120} INFO - ::group::Pre task execution logs
[2025-05-02T15:38:13.650+0000] {taskinstance.py:2076} INFO - Dependencies all met for dep_context=non-requeueable deps ti=<TaskInstance: weather_data_pipeline.collect_data manual__2025-05-02T15:38:09.925719+00:00 [queued]>
[2025-05-02T15:38:13.663+0000] {taskinstance.py:2076} INFO - Dependencies all met for dep_context=requeueable deps ti=<TaskInstance: weather_data_pipeline.collect_data manual__2025-05-02T15:38:09.925719+00:00 [queued]>
[2025-05-02T15:38:13.664+0000] {taskinstance.py:2306} INFO - Starting attempt 1 of 1
[2025-05-02T15:38:13.689+0000] {taskinstance.py:2330} INFO - Executing <Task(BashOperator): collect_data> on 2025-05-02 15:38:09.925719+00:00
[2025-05-02T15:38:13.715+0000] {warnings.py:110} WARNING - /home/***/.local/lib/python3.12/site-packages/***/task/task_runner/standard_task_runner.py:61: DeprecationWarning: This process (pid=340) is multi-threaded, use of fork() may lead to deadlocks in the child.
  pid = os.fork()

[2025-05-02T15:38:13.721+0000] {standard_task_runner.py:63} INFO - Started process 342 to run task
[2025-05-02T15:38:13.723+0000] {standard_task_runner.py:90} INFO - Running: ['***', 'tasks', 'run', 'weather_data_pipeline', 'collect_data', 'manual__2025-05-02T15:38:09.925719+00:00', '--job-id', '7', '--raw', '--subdir', 'DAGS_FOLDER/weather_pipeline_dag.py', '--cfg-path', '/tmp/tmp35tr8aja']
[2025-05-02T15:38:13.743+0000] {standard_task_runner.py:91} INFO - Job 7: Subtask collect_data
[2025-05-02T15:38:13.814+0000] {task_command.py:426} INFO - Running <TaskInstance: weather_data_pipeline.collect_data manual__2025-05-02T15:38:09.925719+00:00 [running]> on host e6c0ecc70174
[2025-05-02T15:38:13.908+0000] {taskinstance.py:2648} INFO - Exporting env vars: AIRFLOW_CTX_DAG_OWNER='***' AIRFLOW_CTX_DAG_ID='weather_data_pipeline' AIRFLOW_CTX_TASK_ID='collect_data' AIRFLOW_CTX_EXECUTION_DATE='2025-05-02T15:38:09.925719+00:00' AIRFLOW_CTX_TRY_NUMBER='1' AIRFLOW_CTX_DAG_RUN_ID='manual__2025-05-02T15:38:09.925719+00:00'
[2025-05-02T15:38:13.910+0000] {taskinstance.py:430} INFO - ::endgroup::
[2025-05-02T15:38:13.917+0000] {subprocess.py:63} INFO - Tmp dir root location: /tmp
[2025-05-02T15:38:13.922+0000] {subprocess.py:75} INFO - Running command: ['/usr/bin/bash', '-c', 'python "D:/Semester 8/mlops/Assignment03/Mlops-Assignment03/scripts/collect_data.py"']
[2025-05-02T15:38:13.953+0000] {subprocess.py:86} INFO - Output:
[2025-05-02T15:38:14.099+0000] {subprocess.py:93} INFO - python: can't open file '/tmp/***tmphawcpc3q/D:/Semester 8/mlops/Assignment03/Mlops-Assignment03/scripts/collect_data.py': [Errno 2] No such file or directory
[2025-05-02T15:38:14.104+0000] {subprocess.py:97} INFO - Command exited with return code 2
[2025-05-02T15:38:14.106+0000] {taskinstance.py:441} INFO - ::group::Post task execution logs
[2025-05-02T15:38:14.117+0000] {taskinstance.py:2905} ERROR - Task failed with exception
Traceback (most recent call last):
  File "/home/airflow/.local/lib/python3.12/site-packages/airflow/models/taskinstance.py", line 465, in _execute_task
    result = _execute_callable(context=context, **execute_callable_kwargs)
             ^^^^^^^^^^^^^^^^^^^^^^^^^^^^^^^^^^^^^^^^^^^^^^^^^^^^^^^^^^^^^
  File "/home/airflow/.local/lib/python3.12/site-packages/airflow/models/taskinstance.py", line 432, in _execute_callable
    return execute_callable(context=context, **execute_callable_kwargs)
           ^^^^^^^^^^^^^^^^^^^^^^^^^^^^^^^^^^^^^^^^^^^^^^^^^^^^^^^^^^^^
  File "/home/airflow/.local/lib/python3.12/site-packages/airflow/models/baseoperator.py", line 400, in wrapper
    return func(self, *args, **kwargs)
           ^^^^^^^^^^^^^^^^^^^^^^^^^^^
  File "/home/airflow/.local/lib/python3.12/site-packages/airflow/operators/bash.py", line 243, in execute
    raise AirflowException(
airflow.exceptions.AirflowException: Bash command failed. The command returned a non-zero exit code 2.
[2025-05-02T15:38:14.124+0000] {taskinstance.py:1206} INFO - Marking task as FAILED. dag_id=weather_data_pipeline, task_id=collect_data, run_id=manual__2025-05-02T15:38:09.925719+00:00, execution_date=20250502T153809, start_date=20250502T153813, end_date=20250502T153814
[2025-05-02T15:38:14.138+0000] {standard_task_runner.py:110} ERROR - Failed to execute job 7 for task collect_data (Bash command failed. The command returned a non-zero exit code 2.; 342)
[2025-05-02T15:38:14.187+0000] {local_task_job_runner.py:240} INFO - Task exited with return code 1
[2025-05-02T15:38:14.222+0000] {taskinstance.py:3498} INFO - 0 downstream tasks scheduled from follow-on schedule check
[2025-05-02T15:38:14.228+0000] {local_task_job_runner.py:222} INFO - ::endgroup::
