[2025-05-02T15:29:19.747+0000] {local_task_job_runner.py:120} INFO - ::group::Pre task execution logs
[2025-05-02T15:29:19.768+0000] {taskinstance.py:2076} INFO - Dependencies all met for dep_context=non-requeueable deps ti=<TaskInstance: weather_data_pipeline.collect_data manual__2025-05-02T15:29:16.639039+00:00 [queued]>
[2025-05-02T15:29:19.778+0000] {taskinstance.py:2076} INFO - Dependencies all met for dep_context=requeueable deps ti=<TaskInstance: weather_data_pipeline.collect_data manual__2025-05-02T15:29:16.639039+00:00 [queued]>
[2025-05-02T15:29:19.781+0000] {taskinstance.py:2306} INFO - Starting attempt 1 of 1
[2025-05-02T15:29:19.797+0000] {taskinstance.py:2330} INFO - Executing <Task(BashOperator): collect_data> on 2025-05-02 15:29:16.639039+00:00
[2025-05-02T15:29:19.819+0000] {warnings.py:110} WARNING - /home/***/.local/lib/python3.12/site-packages/***/task/task_runner/standard_task_runner.py:61: DeprecationWarning: This process (pid=226) is multi-threaded, use of fork() may lead to deadlocks in the child.
  pid = os.fork()

[2025-05-02T15:29:19.822+0000] {standard_task_runner.py:90} INFO - Running: ['***', 'tasks', 'run', 'weather_data_pipeline', 'collect_data', 'manual__2025-05-02T15:29:16.639039+00:00', '--job-id', '5', '--raw', '--subdir', 'DAGS_FOLDER/weather_pipeline_dag.py', '--cfg-path', '/tmp/tmp19jdcq5a']
[2025-05-02T15:29:19.831+0000] {standard_task_runner.py:63} INFO - Started process 228 to run task
[2025-05-02T15:29:19.832+0000] {standard_task_runner.py:91} INFO - Job 5: Subtask collect_data
[2025-05-02T15:29:19.888+0000] {task_command.py:426} INFO - Running <TaskInstance: weather_data_pipeline.collect_data manual__2025-05-02T15:29:16.639039+00:00 [running]> on host e6c0ecc70174
[2025-05-02T15:29:20.038+0000] {taskinstance.py:2648} INFO - Exporting env vars: AIRFLOW_CTX_DAG_OWNER='***' AIRFLOW_CTX_DAG_ID='weather_data_pipeline' AIRFLOW_CTX_TASK_ID='collect_data' AIRFLOW_CTX_EXECUTION_DATE='2025-05-02T15:29:16.639039+00:00' AIRFLOW_CTX_TRY_NUMBER='1' AIRFLOW_CTX_DAG_RUN_ID='manual__2025-05-02T15:29:16.639039+00:00'
[2025-05-02T15:29:20.041+0000] {taskinstance.py:430} INFO - ::endgroup::
[2025-05-02T15:29:20.042+0000] {subprocess.py:63} INFO - Tmp dir root location: /tmp
[2025-05-02T15:29:20.044+0000] {subprocess.py:75} INFO - Running command: ['/usr/bin/bash', '-c', 'python /opt/***/scripts/collect_data.py']
[2025-05-02T15:29:20.065+0000] {subprocess.py:86} INFO - Output:
[2025-05-02T15:29:20.177+0000] {subprocess.py:93} INFO - python: can't open file '/opt/***/scripts/collect_data.py': [Errno 2] No such file or directory
[2025-05-02T15:29:20.181+0000] {subprocess.py:97} INFO - Command exited with return code 2
[2025-05-02T15:29:20.182+0000] {taskinstance.py:441} INFO - ::group::Post task execution logs
[2025-05-02T15:29:20.200+0000] {taskinstance.py:2905} ERROR - Task failed with exception
Traceback (most recent call last):
  File "/home/airflow/.local/lib/python3.12/site-packages/airflow/models/taskinstance.py", line 465, in _execute_task
    result = _execute_callable(context=context, **execute_callable_kwargs)
             ^^^^^^^^^^^^^^^^^^^^^^^^^^^^^^^^^^^^^^^^^^^^^^^^^^^^^^^^^^^^^
  File "/home/airflow/.local/lib/python3.12/site-packages/airflow/models/taskinstance.py", line 432, in _execute_callable
    return execute_callable(context=context, **execute_callable_kwargs)
           ^^^^^^^^^^^^^^^^^^^^^^^^^^^^^^^^^^^^^^^^^^^^^^^^^^^^^^^^^^^^
  File "/home/airflow/.local/lib/python3.12/site-packages/airflow/models/baseoperator.py", line 400, in wrapper
    return func(self, *args, **kwargs)
           ^^^^^^^^^^^^^^^^^^^^^^^^^^^
  File "/home/airflow/.local/lib/python3.12/site-packages/airflow/operators/bash.py", line 243, in execute
    raise AirflowException(
airflow.exceptions.AirflowException: Bash command failed. The command returned a non-zero exit code 2.
[2025-05-02T15:29:20.208+0000] {taskinstance.py:1206} INFO - Marking task as FAILED. dag_id=weather_data_pipeline, task_id=collect_data, run_id=manual__2025-05-02T15:29:16.639039+00:00, execution_date=20250502T152916, start_date=20250502T152919, end_date=20250502T152920
[2025-05-02T15:29:20.224+0000] {standard_task_runner.py:110} ERROR - Failed to execute job 5 for task collect_data (Bash command failed. The command returned a non-zero exit code 2.; 228)
[2025-05-02T15:29:20.249+0000] {local_task_job_runner.py:240} INFO - Task exited with return code 1
[2025-05-02T15:29:20.299+0000] {taskinstance.py:3498} INFO - 0 downstream tasks scheduled from follow-on schedule check
[2025-05-02T15:29:20.306+0000] {local_task_job_runner.py:222} INFO - ::endgroup::
