[2025-05-02T16:36:20.978+0000] {local_task_job_runner.py:120} INFO - ::group::Pre task execution logs
[2025-05-02T16:36:20.999+0000] {taskinstance.py:2073} INFO - Dependencies all met for dep_context=non-requeueable deps ti=<TaskInstance: weather_data_pipeline.preprocess_data manual__2025-05-02T16:36:09.916573+00:00 [queued]>
[2025-05-02T16:36:21.006+0000] {taskinstance.py:2073} INFO - Dependencies all met for dep_context=requeueable deps ti=<TaskInstance: weather_data_pipeline.preprocess_data manual__2025-05-02T16:36:09.916573+00:00 [queued]>
[2025-05-02T16:36:21.007+0000] {taskinstance.py:2303} INFO - Starting attempt 1 of 1
[2025-05-02T16:36:21.019+0000] {taskinstance.py:2327} INFO - Executing <Task(BashOperator): preprocess_data> on 2025-05-02 16:36:09.916573+00:00
[2025-05-02T16:36:21.028+0000] {warnings.py:110} WARNING - /home/***/.local/lib/python3.12/site-packages/***/task/task_runner/standard_task_runner.py:61: DeprecationWarning: This process (pid=108) is multi-threaded, use of fork() may lead to deadlocks in the child.
  pid = os.fork()

[2025-05-02T16:36:21.030+0000] {standard_task_runner.py:63} INFO - Started process 110 to run task
[2025-05-02T16:36:21.028+0000] {standard_task_runner.py:90} INFO - Running: ['***', 'tasks', 'run', 'weather_data_pipeline', 'preprocess_data', 'manual__2025-05-02T16:36:09.916573+00:00', '--job-id', '57', '--raw', '--subdir', 'DAGS_FOLDER/weather_pipeline_dag.py', '--cfg-path', '/tmp/tmp__1gko6c']
[2025-05-02T16:36:21.031+0000] {standard_task_runner.py:91} INFO - Job 57: Subtask preprocess_data
[2025-05-02T16:36:21.080+0000] {task_command.py:426} INFO - Running <TaskInstance: weather_data_pipeline.preprocess_data manual__2025-05-02T16:36:09.916573+00:00 [running]> on host b0cbeac4e64c
[2025-05-02T16:36:21.142+0000] {taskinstance.py:2644} INFO - Exporting env vars: AIRFLOW_CTX_DAG_OWNER='***' AIRFLOW_CTX_DAG_ID='weather_data_pipeline' AIRFLOW_CTX_TASK_ID='preprocess_data' AIRFLOW_CTX_EXECUTION_DATE='2025-05-02T16:36:09.916573+00:00' AIRFLOW_CTX_TRY_NUMBER='1' AIRFLOW_CTX_DAG_RUN_ID='manual__2025-05-02T16:36:09.916573+00:00'
[2025-05-02T16:36:21.144+0000] {taskinstance.py:430} INFO - ::endgroup::
[2025-05-02T16:36:21.147+0000] {subprocess.py:63} INFO - Tmp dir root location: /tmp
[2025-05-02T16:36:21.148+0000] {subprocess.py:75} INFO - Running command: ['/usr/bin/bash', '-c', 'python /opt/***/scripts/preprocess_data.py']
[2025-05-02T16:36:21.160+0000] {subprocess.py:86} INFO - Output:
[2025-05-02T16:36:23.188+0000] {subprocess.py:93} INFO - Traceback (most recent call last):
[2025-05-02T16:36:23.192+0000] {subprocess.py:93} INFO -   File "/opt/***/scripts/preprocess_data.py", line 15, in <module>
[2025-05-02T16:36:23.193+0000] {subprocess.py:93} INFO -     df = pd.read_csv('data/raw/raw_data.csv')
[2025-05-02T16:36:23.193+0000] {subprocess.py:93} INFO -          ^^^^^^^^^^^^^^^^^^^^^^^^^^^^^^^^^^^^
[2025-05-02T16:36:23.193+0000] {subprocess.py:93} INFO -   File "/home/***/.local/lib/python3.12/site-packages/pandas/io/parsers/readers.py", line 948, in read_csv
[2025-05-02T16:36:23.194+0000] {subprocess.py:93} INFO -     return _read(filepath_or_buffer, kwds)
[2025-05-02T16:36:23.194+0000] {subprocess.py:93} INFO -            ^^^^^^^^^^^^^^^^^^^^^^^^^^^^^^^
[2025-05-02T16:36:23.194+0000] {subprocess.py:93} INFO -   File "/home/***/.local/lib/python3.12/site-packages/pandas/io/parsers/readers.py", line 611, in _read
[2025-05-02T16:36:23.194+0000] {subprocess.py:93} INFO -     parser = TextFileReader(filepath_or_buffer, **kwds)
[2025-05-02T16:36:23.195+0000] {subprocess.py:93} INFO -              ^^^^^^^^^^^^^^^^^^^^^^^^^^^^^^^^^^^^^^^^^^
[2025-05-02T16:36:23.195+0000] {subprocess.py:93} INFO -   File "/home/***/.local/lib/python3.12/site-packages/pandas/io/parsers/readers.py", line 1448, in __init__
[2025-05-02T16:36:23.195+0000] {subprocess.py:93} INFO -     self._engine = self._make_engine(f, self.engine)
[2025-05-02T16:36:23.196+0000] {subprocess.py:93} INFO -                    ^^^^^^^^^^^^^^^^^^^^^^^^^^^^^^^^^
[2025-05-02T16:36:23.196+0000] {subprocess.py:93} INFO -   File "/home/***/.local/lib/python3.12/site-packages/pandas/io/parsers/readers.py", line 1705, in _make_engine
[2025-05-02T16:36:23.196+0000] {subprocess.py:93} INFO -     self.handles = get_handle(
[2025-05-02T16:36:23.196+0000] {subprocess.py:93} INFO -                    ^^^^^^^^^^^
[2025-05-02T16:36:23.197+0000] {subprocess.py:93} INFO -   File "/home/***/.local/lib/python3.12/site-packages/pandas/io/common.py", line 863, in get_handle
[2025-05-02T16:36:23.197+0000] {subprocess.py:93} INFO -     handle = open(
[2025-05-02T16:36:23.197+0000] {subprocess.py:93} INFO -              ^^^^^
[2025-05-02T16:36:23.198+0000] {subprocess.py:93} INFO - FileNotFoundError: [Errno 2] No such file or directory: 'data/raw/raw_data.csv'
[2025-05-02T16:36:23.443+0000] {subprocess.py:97} INFO - Command exited with return code 1
[2025-05-02T16:36:23.452+0000] {taskinstance.py:441} INFO - ::group::Post task execution logs
[2025-05-02T16:36:23.542+0000] {taskinstance.py:2890} ERROR - Task failed with exception
Traceback (most recent call last):
  File "/home/airflow/.local/lib/python3.12/site-packages/airflow/models/taskinstance.py", line 465, in _execute_task
    result = _execute_callable(context=context, **execute_callable_kwargs)
             ^^^^^^^^^^^^^^^^^^^^^^^^^^^^^^^^^^^^^^^^^^^^^^^^^^^^^^^^^^^^^
  File "/home/airflow/.local/lib/python3.12/site-packages/airflow/models/taskinstance.py", line 432, in _execute_callable
    return execute_callable(context=context, **execute_callable_kwargs)
           ^^^^^^^^^^^^^^^^^^^^^^^^^^^^^^^^^^^^^^^^^^^^^^^^^^^^^^^^^^^^
  File "/home/airflow/.local/lib/python3.12/site-packages/airflow/models/baseoperator.py", line 400, in wrapper
    return func(self, *args, **kwargs)
           ^^^^^^^^^^^^^^^^^^^^^^^^^^^
  File "/home/airflow/.local/lib/python3.12/site-packages/airflow/operators/bash.py", line 243, in execute
    raise AirflowException(
airflow.exceptions.AirflowException: Bash command failed. The command returned a non-zero exit code 1.
[2025-05-02T16:36:23.550+0000] {taskinstance.py:1205} INFO - Marking task as FAILED. dag_id=weather_data_pipeline, task_id=preprocess_data, execution_date=20250502T163609, start_date=20250502T163621, end_date=20250502T163623
[2025-05-02T16:36:23.570+0000] {standard_task_runner.py:110} ERROR - Failed to execute job 57 for task preprocess_data (Bash command failed. The command returned a non-zero exit code 1.; 110)
[2025-05-02T16:36:23.586+0000] {local_task_job_runner.py:240} INFO - Task exited with return code 1
[2025-05-02T16:36:23.606+0000] {taskinstance.py:3482} INFO - 0 downstream tasks scheduled from follow-on schedule check
[2025-05-02T16:36:23.608+0000] {local_task_job_runner.py:222} INFO - ::endgroup::
